Workbook

Sheet Assumptions
A1: QC Cost Model — Assumptions
A2: Blue = input you can change. Every other sheet references these cells. MarketSquare, 14 Aug 2026.
A5: Input | B5: Value | C5: Unit | D5: Source
A6: MODEL PRICES — $ per 1,000,000 tokens | D6: ai_price_card.json v2026-08-01.1 — the authoritative register; no doc may cite a price not on this card
A7: Haiku 4-5 input | B7: 1 | C7: $/Mtok | D7: ai_price_card.json:44-48
A8: Haiku 4-5 output | B8: 5 | C8: $/Mtok | D8: ai_price_card.json:44-48
A9: Sonnet 4-6 input | B9: 3 | C9: $/Mtok | D9: ai_price_card.json:91-95
A10: Sonnet 4-6 output | B10: 15 | C10: $/Mtok | D10: ai_price_card.json:91-95
A11: GPT-5.6 Luna input | B11: 0.2 | C11: $/Mtok | D11: ai_price_card.json:199-203 — cheapest lane, gate: golden-set-passed
A12: GPT-5.6 Luna output | B12: 1.2 | C12: $/Mtok | D12: ai_price_card.json:199-203
A13: Mistral-medium-3.5 input (EUR) | B13: 1.5 | C13: EUR/Mtok | D13: ai_price_card.json:131-135
A14: Mistral-medium-3.5 output (EUR) | B14: 7.5 | C14: EUR/Mtok | D14: ai_price_card.json:131-135
A15: EUR->USD incl. 5% buffer | B15: 1.155 | C15: x | D15: ai_price_card.json:35-40 (EUR_USD 1.1 x buffer_pct 5)
A16: CALL SHAPE
A17: Tokens per photo | B17: 1806 | C17: tok | D17: Anthropic (w x h)/750 rule at 1344px — AI_PHOTO_COST_MODEL.xlsx 'Per-photo model'
A18: QC spec + inspector system prompt | B18: 200 | C18: tok | D18: ai_qc.py — numbered criteria + _CHECKER_SYSTEM
A19: QC verdict output | B19: 60 | C19: tok | D19: JSON verdict; ai_qc.py caps the checker at max_tokens=400
A20: Retry rate — p(check fails, one redo) | B20: 0.1 | C20: frac | D20: Prudent. AdvertAgent_AI_CostModel.xlsx r17 uses a 7% failure/retry token loading
A21: VOLUMES — Year 1 | D21: MarketSquare_Cost_Breakdown_v2_AIcosts.xlsx '3-Year Summary' + 'AI Costs Rev B'
A22: Sellers Y1 | B22: 7790 | C22: count | D22: 3-Year Summary Y1
A23: Listings per seller | B23: 1.5 | C23: x | D23: AI Costs Rev B r6
A24: Photos per listing | B24: 16.8 | C24: count | D24: AI Costs Rev B r7 (24 cap x 70%)
A25: Agency-import share of listings | B25: 0.1 | C25: frac | D25: ESTIMATE — no repo figure found. Change me.
A26: Graded cards Y1 | B26: 5000 | C26: count | D26: ESTIMATE — collectables subset. Change me.
A27: Inbound emails/day | B27: 20 | C27: count | D27: ESTIMATE — no repo figure found. Change me.
A28: AS-03 moderation sample rate | B28: 0.1 | C28: frac | D28: POLICY LEVER — fraction of ACCEPTED photos cross-checked. See 'Policy Options'
A29: P&L — Year 1 baseline | D29: MarketSquare_Cost_Breakdown_v2_AIcosts.xlsx '3-Year Summary'
A30: Revenue Y1 | B30: 235154 | C30: $ | D30: 3-Year Summary
A31: Total costs Y1 (pre-QC) | B31: 11131.37 | C31: $ | D31: 3-Year Summary
A32: of which AI API cost Y1 | B32: 627 | C32: $ | D32: 3-Year Summary
A33: 1 Tuppence gross | B33: 2 | C33: $ | D33: PRICING_CANON.md:52 — fixed
A34: Paystack effective rate, single-T top-up | B34: 0.05678 | C34: frac | D34: AI Costs Rev B r40 — R36 ticket; worst-margin transaction in the business
A35: Target COGS ceiling per AI function | B35: 0.1 | C35: frac | D35: AdvertAgent/AI_FUNCTION_COST_CEILINGS.md:28,41
A37: LEGEND
A38: Yellow fill + blue text = an input you can change. Everything else is a formula.
A39: Green text on other sheets = a link back to this page.
A40: Two figures are ESTIMATES with no repo source (agency-import share, graded cards, inbound emails). They are marked and easy to flex.
A42: OPTIMISATION LANES & LEVERS (added 14 Aug 2026) | D42: Vision pricing web-checked 14 Aug 2026 (benchlm.ai registry) + AI_PHOTO_COST_MODEL.xlsx 'Pricing (Jul 2026)' web-verified 16 Jul
A43: Gemini 2.5 Flash-Lite input | B43: 0.1 | C43: $/Mtok | D43: benchlm.ai 14 Aug 2026; also in AI_PHOTO_COST_MODEL.xlsx. VISION — must pass failover/eval_golden_set.py before production
A44: Gemini 2.5 Flash-Lite output | B44: 0.4 | C44: $/Mtok | D44: as above; cache-hit rate $0.01/Mtok published
...

Sheet Per-Item Cost
A1: Per-Item Cost — doer vs checker
A2: The checker is cheaper than the doer by design (ai_qc.py constraint 4). Where it is not, sampling is the answer.
A5: ID | B5: Surface | C5: Doer lane | D5: Doer in (tok) | E5: Doer out (tok) | F5: Doer $/item | G5: Checker sees | H5: Checker in (tok) | I5: Chk $ Luna | J5: Chk $ Haiku | K5: Chk $ Mistral | L5: Checker as % of doer (Luna)
A6: AS-01 | B6: KYC identity | C6: Sonnet | D6: =Assumptions!$B$17+300 -> 2106 | E6: 300 | F6: =D6/1000000*Assumptions!$B$9+E6/1000000*Assumptions!$B$10 -> 0.010818 | G6: the image | H6: =Assumptions!$B$18+300+300+1*Assumptions!$B$17 -> 2606 | I6: =H6/1000000*Assumptions!$B$11+Assumptions!$B$19/1000000*Assumptions!$B$12 -> 0.0005932 | J6: =H6/1000000*Assumptions!$B$7+Assumptions!$B$19/1000000*Assumptions!$B$8 -> 0.002906 | K6: =(H6/1000000*Assumptions!$B$13+Assumptions!$B$19/1000000*Assumptions!$B$14)*Assumptions!$B$15 -> 0.005034645 | L6: =IFERROR(I6/F6,0) -> 0.054834535
A7: AS-02 | B7: Anonymisation | C7: Sonnet | D7: =Assumptions!$B$17+650 -> 2456 | E7: 1400 | F7: =D7/1000000*Assumptions!$B$9+E7/1000000*Assumptions!$B$10 -> 0.028368 | G7: the image | H7: =Assumptions!$B$18+200+200+1*Assumptions!$B$17 -> 2406 | I7: =H7/1000000*Assumptions!$B$11+Assumptions!$B$19/1000000*Assumptions!$B$12 -> 0.0005532 | J7: =H7/1000000*Assumptions!$B$7+Assumptions!$B$19/1000000*Assumptions!$B$8 -> 0.002706 | K7: =(H7/1000000*Assumptions!$B$13+Assumptions!$B$19/1000000*Assumptions!$B$14)*Assumptions!$B$15 -> 0.004688145 | L7: =IFERROR(I7/F7,0) -> 0.019500846
A8: AS-03 | B8: Photo moderation | C8: Haiku | D8: =Assumptions!$B$17+120 -> 1926 | E8: 8 | F8: =D8/1000000*Assumptions!$B$7+E8/1000000*Assumptions!$B$8 -> 0.001966 | G8: the image | H8: =Assumptions!$B$18+120+50+1*Assumptions!$B$17 -> 2176 | I8: =H8/1000000*Assumptions!$B$11+Assumptions!$B$19/1000000*Assumptions!$B$12 -> 0.0005072 | J8: =H8/1000000*Assumptions!$B$7+Assumptions!$B$19/1000000*Assumptions!$B$8 -> 0.002476 | K8: =(H8/1000000*Assumptions!$B$13+Assumptions!$B$19/1000000*Assumptions!$B$14)*Assumptions!$B$15 -> 0.00428967 | L8: =IFERROR(I8/F8,0) -> 0.25798576
A9: AS-05 | B9: Card grading | C9: Haiku | D9: =Assumptions!$B$17+300 -> 2106 | E9: 300 | F9: =D9/1000000*Assumptions!$B$7+E9/1000000*Assumptions!$B$8 -> 0.003606 | G9: the image | H9: =Assumptions!$B$18+300+300+1*Assumptions!$B$17 -> 2606 | I9: =H9/1000000*Assumptions!$B$11+Assumptions!$B$19/1000000*Assumptions!$B$12 -> 0.0005932 | J9: =H9/1000000*Assumptions!$B$7+Assumptions!$B$19/1000000*Assumptions!$B$8 -> 0.002906 | K9: =(H9/1000000*Assumptions!$B$13+Assumptions!$B$19/1000000*Assumptions!$B$14)*Assumptions!$B$15 -> 0.005034645 | L9: =IFERROR(I9/F9,0) -> 0.16450361
A10: AS-09 | B10: Listing draft | C10: Haiku | D10: =3*Assumptions!$B$17+300 -> 5718 | E10: 700 | F10: =D10/1000000*Assumptions!$B$7+E10/1000000*Assumptions!$B$8 -> 0.009218 | G10: text only | H10: =Assumptions!$B$18+300+700+0*Assumptions!$B$17 -> 1200 | I10: =H10/1000000*Assumptions!$B$11+Assumptions!$B$19/1000000*Assumptions!$B$12 -> 0.000312 | J10: =H10/1000000*Assumptions!$B$7+Assumptions!$B$19/1000000*Assumptions!$B$8 -> 0.0015 | K10: =(H10/1000000*Assumptions!$B$13+Assumptions!$B$19/1000000*Assumptions!$B$14)*Assumptions!$B$15 -> 0.00259875 | L10: =IFERROR(I10/F10,0) -> 0.033846821
A11: AS-08 | B11: Email triage | C11: Haiku | D11: =1500 -> 1500 | E11: 400 | F11: =D11/1000000*Assumptions!$B$7+E11/1000000*Assumptions!$B$8 -> 0.0035 | G11: text only | H11: =Assumptions!$B$18+1500+400+0*Assumptions!$B$17 -> 2100 | I11: =H11/1000000*Assumptions!$B$11+Assumptions!$B$19/1000000*Assumptions!$B$12 -> 0.000492 | J11: =H11/1000000*Assumptions!$B$7+Assumptions!$B$19/1000000*Assumptions!$B$8 -> 0.0024 | K11: =(H11/1000000*Assumptions!$B$13+Assumptions!$B$19/1000000*Assumptions!$B$14)*Assumptions!$B$15 -> 0.004158 | L11: =IFERROR(I11/F11,0) -> 0.14057143
A13: Cross-vendor is not only more independent, it is CHEAPER: Luna at $0.20/$1.20 is 5x under Haiku.
A14: AS-03 is the exception — its doer emits 8 tokens, so a checker that must re-view the image costs MORE than the doer. That surface gets sampled, not skipped.
A15: 'text only' means the checker inspects the text artefact and never re-reads the images — the cheap case, and it covers the listing-draft criteria in full.

Sheet Annual Impact
A1: Annual Impact — Year 1
A2: Volumes drive off Assumptions. QC adder is compared against the Y1 AI API line and the 95.27% operating margin.
A5: ID | B5: Surface | C5: Volume Y1 | D5: Volume basis | E5: Doer $/yr | F5: QC $/yr (Luna) | G5: QC $/yr (Haiku) | H5: Retry $/yr | I5: QC as % of doer
A6: AS-01 | B6: KYC identity | C6: =Assumptions!$B$22 -> 7790 | D6: one verification per seller | E6: ='Per-Item Cost'!F6*C6 -> 84.27222 | F6: ='Per-Item Cost'!I6*C6 -> 4.621028 | G6: ='Per-Item Cost'!J6*C6 -> 22.63774 | H6: =(E6+F6)*Assumptions!$B$20 -> 8.8893248 | I6: =IFERROR(F6/E6,0) -> 0.054834535
A7: AS-02 | B7: Anonymisation | C7: =Assumptions!$B$22*Assumptions!$B$23*Assumptions!$B$25*Assumptions!$B$24 -> 19630.8 | D7: agency-import photos through the anonymity gate | E7: ='Per-Item Cost'!F7*C7 -> 556.88653 | F7: ='Per-Item Cost'!I7*C7 -> 10.859759 | G7: ='Per-Item Cost'!J7*C7 -> 53.120945 | H7: =(E7+F7)*Assumptions!$B$20 -> 56.774629 | I7: =IFERROR(F7/E7,0) -> 0.019500846
A8: AS-03 | B8: Photo moderation | C8: =Assumptions!$B$22*Assumptions!$B$23*Assumptions!$B$24 -> 196308 | D8: every photo uploaded | E8: ='Per-Item Cost'!F8*C8 -> 385.94153 | F8: ='Per-Item Cost'!I8*C8*Assumptions!$B$28 -> 9.9567418 | G8: ='Per-Item Cost'!J8*C8*Assumptions!$B$28 -> 48.605861 | H8: =(E8+F8)*Assumptions!$B$20 -> 39.589827 | I8: =IFERROR(F8/E8,0) -> 0.025798576
A9: AS-05 | B9: Card grading | C9: =Assumptions!$B$26 -> 5000 | D9: graded collectables | E9: ='Per-Item Cost'!F9*C9 -> 18.03 | F9: ='Per-Item Cost'!I9*C9 -> 2.966 | G9: ='Per-Item Cost'!J9*C9 -> 14.53 | H9: =(E9+F9)*Assumptions!$B$20 -> 2.0996 | I9: =IFERROR(F9/E9,0) -> 0.16450361
A10: AS-09 | B10: Listing draft | C10: =Assumptions!$B$22*Assumptions!$B$23 -> 11685 | D10: one draft per listing | E10: ='Per-Item Cost'!F10*C10 -> 107.71233 | F10: ='Per-Item Cost'!I10*C10 -> 3.64572 | G10: ='Per-Item Cost'!J10*C10 -> 17.5275 | H10: =(E10+F10)*Assumptions!$B$20 -> 11.135805 | I10: =IFERROR(F10/E10,0) -> 0.033846821
A11: AS-08 | B11: Email triage | C11: =Assumptions!$B$27*365 -> 7300 | D11: inbound mail | E11: ='Per-Item Cost'!F11*C11 -> 25.55 | F11: ='Per-Item Cost'!I11*C11 -> 3.5916 | G11: ='Per-Item Cost'!J11*C11 -> 17.52 | H11: =(E11+F11)*Assumptions!$B$20 -> 2.91416 | I11: =IFERROR(F11/E11,0) -> 0.14057143
B12: TOTAL | E12: =SUM(E6:E11) -> 1178.3926 | F12: =SUM(F6:F11) -> 35.640848 | G12: =SUM(G6:G11) -> 173.94205 | H12: =SUM(H6:H11) -> 121.40335
A14: P&L EFFECT
A15: Scenario | B15: QC adder $/yr | C15: Total costs $/yr | D15: Net income $/yr | E15: Operating margin | F15: Change vs baseline
A16: Baseline — no QC | B16: =0 -> 0 | C16: =Assumptions!$B$31+B16 -> 11131.37 | D16: =Assumptions!$B$30-C16 -> 224022.63 | E16: =D16/Assumptions!$B$30 -> 0.95266349 | F16: =E16-E$16 -> 0
A17: QC, cross-vendor Luna checker | B17: =F12+H12 -> 157.04419 | C17: =Assumptions!$B$31+B17 -> 11288.414 | D17: =Assumptions!$B$30-C17 -> 223865.59 | E17: =D17/Assumptions!$B$30 -> 0.95199565 | F17: =E17-E$16 -> -0.00066783552
A18: QC, same-lane Haiku checker | B18: =G12+H12*1.6 -> 368.1874 | C18: =Assumptions!$B$31+B18 -> 11499.557 | D18: =Assumptions!$B$30-C18 -> 223654.44 | E18: =D18/Assumptions!$B$30 -> 0.95109776 | F18: =E18-E$16 -> -0.0015657288
A20: QC adder as a % of the Y1 AI API line | B20: =B17/Assumptions!$B$32 -> 0.25046921
A21: QC adder as a % of Y1 revenue | B21: =B17/Assumptions!$B$30 -> 0.00066783552
A23: Every QC candidate sits on a FREE surface — none of these six charges Tuppence. So QC adds unbilled COGS; it does not reduce revenue.
A24: That is the honest shape of it: the cost lands entirely on the cost side, and it is still immaterial at the P&L level.

Sheet Policy Options
A1: Policy Options — AS-03 is the only real decision
A2: Every other surface is cheap enough to QC at 100%. Photo moderation is the one that needs a sampling call.
A5: AS-03 sample rate | B5: QC $/yr (Luna) | C5: QC $/yr (Haiku) | D5: What it buys
A6: 1 | B6: ='Per-Item Cost'!I8*'Annual Impact'!C8*A6 -> 99.567418 | C6: ='Per-Item Cost'!J8*'Annual Impact'!C8*A6 -> 486.05861 | D6: Every accepted photo cross-checked. Maximum assurance, and still under $100/yr on Luna.
A7: 0.25 | B7: ='Per-Item Cost'!I8*'Annual Impact'!C8*A7 -> 24.891854 | C7: ='Per-Item Cost'!J8*'Annual Impact'!C8*A7 -> 121.51465 | D7: Strong detection of a systematic blind spot within days.
A8: 0.1 | B8: ='Per-Item Cost'!I8*'Annual Impact'!C8*A8 -> 9.9567418 | C8: ='Per-Item Cost'!J8*'Annual Impact'!C8*A8 -> 48.605861 | D8: RECOMMENDED. Detects a systematic failure quickly; will miss a rare one-off, which the appeal route catches.
A9: 0.05 | B9: ='Per-Item Cost'!I8*'Annual Impact'!C8*A9 -> 4.9783709 | C9: ='Per-Item Cost'!J8*'Annual Impact'!C8*A9 -> 24.30293 | D9: Thin. Only justified if the moderation lane has a long clean record.
A10: 0 | B10: ='Per-Item Cost'!I8*'Annual Impact'!C8*A10 -> 0 | C10: ='Per-Item Cost'!J8*'Annual Impact'!C8*A10 -> 0 | D10: No QC. The false ACCEPT stays invisible — nobody appeals an accept.
A13: RECOMMENDED POLICY
A14: 1. QC at 100% on every RED and AMBER surface whose checker inspects TEXT — the cost is rounding error.
A15: 2. QC at 100% on RED surfaces whose checker must re-view an image, EXCEPT AS-03.
A16: 3. AS-03 photo moderation: sample the ACCEPTS at 10%. Rejects self-correct via appeal; accepts are silent.
A17: 4. No QC on GREEN surfaces (search interpretation, market note). Nothing there is worth a second call.
A18: 5. Checker runs on the cheapest configured NON-primary lane. Independence and cost point the same way.
A19: 6. Cap QC spend as its own line so it can never crowd out doer spend under the $100/day platform ceiling.

Sheet Optimised
A1: Optimised — right model, right resolution, batched QC
A2: The checker moves to the cheap lane NOW (a constrained task against explicit criteria is easier than generating). The DOER moves only after failover/eval_golden_set.py passes — quality is a gate, not a weight.
A5: Surface | B5: Volume Y1 | C5: Doer today $/yr | D5: Doer optimised $/yr | E5: QC today $/yr | F5: QC optimised $/yr (batched) | G5: TOTAL today | H5: TOTAL optimised | I5: Saving
A6: AS-03 Photo moderation | B6: ='Annual Impact'!C8 -> 196308 | C6: =((Assumptions!$B$49+120)/1000000*Assumptions!$B$7+8/1000000*Assumptions!$B$8)*B6 -> 385.94153 | D6: =((Assumptions!$B$51+120)/1000000*Assumptions!$B$43+8/1000000*Assumptions!$B$44)*B6 -> 14.566054 | E6: =((200+170+Assumptions!$B$49)/1000000*Assumptions!$B$7+Assumptions!$B$19/1000000*Assumptions!$B$8)*B6 -> 486.05861 | F6: =((200+170+Assumptions!$B$51)/1000000*Assumptions!$B$43+Assumptions!$B$19/1000000*Assumptions!$B$44)*B6*(1-Assumptions!$B$53) -> 11.77848 | G6: =C6+E6 -> 872.00014 | H6: =D6+F6 -> 26.344534 | I6: =IFERROR(1-H6/G6,0) -> 0.96978838
A7: AS-01 KYC identity | B7: ='Annual Impact'!C6 -> 7790 | C7: =((Assumptions!$B$49+300)/1000000*Assumptions!$B$9+300/1000000*Assumptions!$B$10)*B7 -> 84.27222 | D7: =((Assumptions!$B$50+300)/1000000*Assumptions!$B$45+300/1000000*Assumptions!$B$46)*B7 -> 12.265355 | E7: =((200+600+Assumptions!$B$49)/1000000*Assumptions!$B$7+Assumptions!$B$19/1000000*Assumptions!$B$8)*B7 -> 22.63774 | F7: =((200+600+Assumptions!$B$50)/1000000*Assumptions!$B$43+Assumptions!$B$19/1000000*Assumptions!$B$44)*B7*(1-Assumptions!$B$53) -> 0.8136655 | G7: =C7+E7 -> 106.90996 | H7: =D7+F7 -> 13.079021 | I7: =IFERROR(1-H7/G7,0) -> 0.87766322
A8: AS-02 Anonymisation | B8: ='Annual Impact'!C7 -> 19630.8 | C8: =((Assumptions!$B$49+650)/1000000*Assumptions!$B$9+1400/1000000*Assumptions!$B$10)*B8 -> 556.88653 | D8: =((Assumptions!$B$51+650)/1000000*Assumptions!$B$45+1400/1000000*Assumptions!$B$46)*B8 -> 94.620456 | E8: =((200+400+Assumptions!$B$49)/1000000*Assumptions!$B$7+Assumptions!$B$19/1000000*Assumptions!$B$8)*B8 -> 53.120945 | F8: =((200+400+Assumptions!$B$51)/1000000*Assumptions!$B$43+Assumptions!$B$19/1000000*Assumptions!$B$44)*B8*(1-Assumptions!$B$53) -> 1.4036022 | G8: =C8+E8 -> 610.00748 | H8: =D8+F8 -> 96.024058 | I8: =IFERROR(1-H8/G8,0) -> 0.84258544
A9: AS-05 Card grading | B9: ='Annual Impact'!C9 -> 5000 | C9: =((Assumptions!$B$49+300)/1000000*Assumptions!$B$7+300/1000000*Assumptions!$B$8)*B9 -> 18.03 | D9: =((Assumptions!$B$51+300)/1000000*Assumptions!$B$43+300/1000000*Assumptions!$B$44)*B9 -> 1.045 | E9: =((200+600+Assumptions!$B$49)/1000000*Assumptions!$B$7+Assumptions!$B$19/1000000*Assumptions!$B$8)*B9 -> 14.53 | F9: =((200+600+Assumptions!$B$51)/1000000*Assumptions!$B$43+Assumptions!$B$19/1000000*Assumptions!$B$44)*B9*(1-Assumptions!$B$53) -> 0.4075 | G9: =C9+E9 -> 32.56 | H9: =D9+F9 -> 1.4525 | I9: =IFERROR(1-H9/G9,0) -> 0.95539005
A10: AS-09 Listing draft | B10: ='Annual Impact'!C10 -> 11685 | C10: =((3*Assumptions!$B$49+300)/1000000*Assumptions!$B$7+700/1000000*Assumptions!$B$8)*B10 -> 107.71233 | D10: =((3*Assumptions!$B$51+300)/1000000*Assumptions!$B$43+700/1000000*Assumptions!$B$44)*B10 -> 5.690595 | E10: =((200+1000)/1000000*Assumptions!$B$7+Assumptions!$B$19/1000000*Assumptions!$B$8)*B10 -> 17.5275 | F10: =((200+1000)/1000000*Assumptions!$B$43+Assumptions!$B$19/1000000*Assumptions!$B$44)*B10*(1-Assumptions!$B$53) -> 0.84132 | G10: =C10+E10 -> 125.23983 | H10: =D10+F10 -> 6.531915 | I10: =IFERROR(1-H10/G10,0) -> 0.94784475
A11: AS-08 Email triage | B11: ='Annual Impact'!C11 -> 7300 | C11: =((1500)/1000000*Assumptions!$B$7+400/1000000*Assumptions!$B$8)*B11 -> 25.55 | D11: =((1500)/1000000*Assumptions!$B$43+400/1000000*Assumptions!$B$44)*B11 -> 2.263 | E11: =((200+1900)/1000000*Assumptions!$B$7+Assumptions!$B$19/1000000*Assumptions!$B$8)*B11 -> 17.52 | F11: =((200+1900)/1000000*Assumptions!$B$43+Assumptions!$B$19/1000000*Assumptions!$B$44)*B11*(1-Assumptions!$B$53) -> 0.8541 | G11: =C11+E11 -> 43.07 | H11: =D11+F11 -> 3.1171 | I11: =IFERROR(1-H11/G11,0) -> 0.92762712
A12: TOTAL | C12: =SUM(C6:C11) -> 1178.3926 | D12: =SUM(D6:D11) -> 130.45046 | E12: =SUM(E6:E11) -> 611.39479 | F12: =SUM(F6:F11) -> 16.098668 | G12: =SUM(G6:G11) -> 1789.7874 | H12: =SUM(H6:H11) -> 146.54913 | I12: =IFERROR(1-H12/G12,0) -> 0.91811925
A14: Optimised total vs the Y1 AI API budget line | C14: =H12/Assumptions!$B$32 -> 0.23373067 | D14: — with 100% QC coverage on every surface, not a sample
A16: THE FOUR LEVERS, IN ORDER OF SIZE
A17: 1. RESOLUTION. Image tokens are (w x h)/750 and dominate every vision call. 1344x1008 = 1,806 tok; 768x576 = 590. A 3.1x cut, free, and 768px is ample to judge an accept/reject or spot a leaked phone number.
A18: ENGINEERING NOTE: for anonymisation, DETECT at low resolution then apply the redaction regions to the FULL-RES image. Never redact at low res.
A19: 2. MODEL. Gemini 2.5 Flash-Lite $0.10/$0.40 is 10x under Haiku; GPT-5 nano $0.05/$0.40 is 20x under. A checker judging against written criteria is a far easier task than generating.
A20: 3. BATCH. QC is asynchronous by nature — nobody waits on a cross-check. Batch APIs are -50%. This is the ideal batch workload and it was left on the table.
A21: 4. CACHING. The QC spec and system prompt are byte-identical on every call. Flash-Lite publishes a cache-hit rate of $0.01/Mtok against $0.10 input — 10x off the constant part.
A23: GATE: the cheap lanes are candidates, not decisions. failover/eval_golden_set.py must pass before ANY doer moves — quality is a gate, not a weight. The CHECKER can move first: it is a constrained task, and a checker that is wrong fails closed.
A24: DOCTRINE: add the cheap lane as an adapter BEHIND the seam, never as a new load-bearing dependency (supplier-fallback doctrine, CLAUDE.md 1 Aug 2026).

Sheet COGS Ceiling Test
A1: COGS Ceiling Test — the paid features
A2: Does adding a checker break the <=10% COGS rule on anything charged in Tuppence? Source: AI_FUNCTION_COST_CEILINGS.md:28,41
A5: Feature | B5: Charged | C5: Doer lane | D5: Doer $ | E5: QC $ (Luna) | F5: Total COGS $ | G5: Gross rev $ | H5: Net rev after Paystack $ | I5: COGS % | J5: Ceiling | K5: Verdict
A6: aa_coach | B6: 1T | C6: Haiku | D6: =2000/1000000*Assumptions!$B$7+1800/1000000*Assumptions!$B$8 -> 0.011 | E6: =(Assumptions!$B$18+2000+1800)/1000000*Assumptions!$B$11+Assumptions!$B$19/1000000*Assumptions!$B$12 -> 0.000872 | F6: =D6+E6 -> 0.011872 | G6: =1*Assumptions!$B$33 -> 2 | H6: =G6*(1-Assumptions!$B$34) -> 1.88644 | I6: =F6/H6 -> 0.0062933356 | J6: =Assumptions!$B$35 -> 0.1 | K6: =IF(I6<=J6,"OK","BREACH") -> OK
A7: ai_listing_rewrite | B7: 1T | C7: Haiku | D7: =1500/1000000*Assumptions!$B$7+350/1000000*Assumptions!$B$8 -> 0.00325 | E7: =(Assumptions!$B$18+1500+350)/1000000*Assumptions!$B$11+Assumptions!$B$19/1000000*Assumptions!$B$12 -> 0.000482 | F7: =D7+E7 -> 0.003732 | G7: =1*Assumptions!$B$33 -> 2 | H7: =G7*(1-Assumptions!$B$34) -> 1.88644 | I7: =F7/H7 -> 0.0019783296 | J7: =Assumptions!$B$35 -> 0.1 | K7: =IF(I7<=J7,"OK","BREACH") -> OK
A8: ai_seller_audit | B8: 1T | C8: Haiku | D8: =1500/1000000*Assumptions!$B$7+400/1000000*Assumptions!$B$8 -> 0.0035 | E8: =(Assumptions!$B$18+1500+400)/1000000*Assumptions!$B$11+Assumptions!$B$19/1000000*Assumptions!$B$12 -> 0.000492 | F8: =D8+E8 -> 0.003992 | G8: =1*Assumptions!$B$33 -> 2 | H8: =G8*(1-Assumptions!$B$34) -> 1.88644 | I8: =F8/H8 -> 0.0021161553 | J8: =Assumptions!$B$35 -> 0.1 | K8: =IF(I8<=J8,"OK","BREACH") -> OK
A9: ai_price_check | B9: 1T | C9: Sonnet | D9: =2000/1000000*Assumptions!$B$9+700/1000000*Assumptions!$B$10 -> 0.0165 | E9: =(Assumptions!$B$18+2000+700)/1000000*Assumptions!$B$11+Assumptions!$B$19/1000000*Assumptions!$B$12 -> 0.000652 | F9: =D9+E9 -> 0.017152 | G9: =1*Assumptions!$B$33 -> 2 | H9: =G9*(1-Assumptions!$B$34) -> 1.88644 | I9: =F9/H9 -> 0.0090922584 | J9: =Assumptions!$B$35 -> 0.1 | K9: =IF(I9<=J9,"OK","BREACH") -> OK
A10: ai_yield_calc | B10: 1T | C10: Haiku | D10: =1500/1000000*Assumptions!$B$7+250/1000000*Assumptions!$B$8 -> 0.00275 | E10: =(Assumptions!$B$18+1500+250)/1000000*Assumptions!$B$11+Assumptions!$B$19/1000000*Assumptions!$B$12 -> 0.000462 | F10: =D10+E10 -> 0.003212 | G10: =1*Assumptions!$B$33 -> 2 | H10: =G10*(1-Assumptions!$B$34) -> 1.88644 | I10: =F10/H10 -> 0.0017026781 | J10: =Assumptions!$B$35 -> 0.1 | K10: =IF(I10<=J10,"OK","BREACH") -> OK
A11: ai_batch_card_listings | B11: 2T | C11: Haiku | D11: =18360/1000000*Assumptions!$B$7+2000/1000000*Assumptions!$B$8 -> 0.02836 | E11: =(Assumptions!$B$18+300+2000)/1000000*Assumptions!$B$11+Assumptions!$B$19/1000000*Assumptions!$B$12 -> 0.000572 | F11: =D11+E11 -> 0.028932 | G11: =2*Assumptions!$B$33 -> 4 | H11: =G11*(1-Assumptions!$B$34) -> 3.77288 | I11: =F11/H11 -> 0.0076684125 | J11: =Assumptions!$B$35 -> 0.1 | K11: =IF(I11<=J11,"OK","BREACH") -> OK
A13: Paystack is applied at the single-T rate (5.678%) — the worst case. Larger packs are cheaper and improve every row.
A14: Headroom is roughly two orders of magnitude. QC could get 10x more expensive and still clear the ceiling.

Sheet Break-even
A1: Break-even — how many prevented defects pay for the QC
A2: A prevented anonymity leak is a preserved introduction fee. That is the cleanest measurable saving in the model.
A5: Surface | B5: QC $/yr | C5: Value of one prevented defect | D5: Basis | E5: Defects/yr to break even | F5: As % of items
A6: AS-02 Anonymisation | B6: ='Annual Impact'!F7 -> 10.859759 | C6: =Assumptions!$B$33*(1-Assumptions!$B$34) -> 1.88644 | D6: One leaked contact = one bypassed introduction = 1T of revenue, permanently | E6: =IFERROR(B6/C6,0) -> 5.7567474 | F6: =IFERROR(E6/'Annual Impact'!C7,0) -> 0.00029325078
A7: AS-01 KYC identity | B7: ='Annual Impact'!F6 -> 4.621028 | C7: =Assumptions!$B$33*(1-Assumptions!$B$34) -> 1.88644 | D7: CONSERVATIVE placeholder — a fraudulent verified seller is worth far more than 1T of damage | E7: =IFERROR(B7/C7,0) -> 2.4496024 | F7: =IFERROR(E7/'Annual Impact'!C6,0) -> 0.00031445474
A8: AS-09 Listing draft | B8: ='Annual Impact'!F10 -> 3.64572 | C8: =Assumptions!$B$33*(1-Assumptions!$B$34) -> 1.88644 | D8: CONSERVATIVE — a misdescription that reaches a buyer is a consumer-law matter, not a lost intro | E8: =IFERROR(B8/C8,0) -> 1.9325926 | F8: =IFERROR(E8/'Annual Impact'!C10,0) -> 0.0001653909
A11: Every value here is deliberately conservative — each prevented defect is valued at a single lost introduction fee.
A12: The real cost of an anonymity breach is the agency relationship (R3), and of a KYC false accept the trust promise (R1). Neither is in these numbers.
A13: Read the break-even column as an upper bound on what QC must achieve to be worth it.

Sheet Budget Findings
A1: Budget Findings — three things that need fixing regardless
A2: Found while building this model. Each is a live budget-control issue, and QC makes each one bigger.
A5: # | B5: Finding | C5: Where | D5: Impact | E5: Action
A6: 1 | B6: Haiku is priced at $0.80/$4.00 in the live cost accounting, but the authoritative price card says $1.00/$5.00 | C6: bea_main.py:1440 vs ai_price_card.json:44-48 | D6: Every Haiku cost written to ai_spend_log is ~20-25% LOW. The $100/day ceiling and the $0.50/user rail are both computed off it, so both are looser than intended. | E6: Correct _MODEL_PRICE to (1.00, 5.00). One-line change; add a ledger entry asserting the code table matches the price card.
A7: 2 | B7: The pre-dispatch hold is $0.06 and does not cover a QC'd call | C7: _AI_WORST_CASE_HOLD_USD, bea_main.py:1759 | D7: A vision doer with 10 images plus a checker plus one retry is roughly $0.175 — nearly 3x the hold. RG-0037 guarantees concurrency cannot overshoot the ceiling; with QC wired in and the hold unchanged, that guarantee quietly stops holding. | E7: Raise the hold, or better: make it a function of the declared call shape (images x per-image tokens + checker + retry) rather than one flat constant.
A8: 3 | B8: AdvertAgent's documented input/search ceilings are not enforced in code | C8: AdvertAgent/service/advert_agent.py:785-791 — no max_in anywhere; live max_searches/max_tokens exceed the doc caps | D8: Worst-case cost per paid run is not bounded by construction, contrary to AI_FUNCTION_COST_CEILINGS.md. Pre-existing, but a QC stage multiplies whatever the true worst case is. | E8: Either enforce the documented caps or restate them to match reality. A ceiling nobody enforces is the same failure mode as a checker nobody checks.
