Workbook

Sheet Read me
A1: TrustSquare · Quick · Trader — translation proofreading table
A2: Source: live database backup 12 Oct 2026 04:40 and the app dictionaries in the MarketSquare project (Trader from the fast-lane branch, not live yet).
A4: Sheets
A5: All strings — every app word or sentence: English on the left, then Afrikaans, isiZulu, isiXhosa, Sepedi.
A6: Afrikaans / isiZulu / isiXhosa / Sepedi review — one sheet per proofreader: English, current text, and yellow columns to fill in.
A7: Content & legal — advert texts, place names, guide and legal passages the app auto-translated on demand (mostly Afrikaans only).
A8: Kept in English — phrases deliberately left in English (legal clauses, acronyms, codes); listed so reviewers do not translate them.
A9: Summary — counts per app and language, calculated from All strings.
A11: Colour code
A12: TrustSquare rows
A13: Quick rows
A14: Trader rows
... A20: How to fill in a review sheet (example)
A21: English | B21: Current Afrikaans | C21: Corrected Afrikaans | D21: Comment
A22: Featured | B22: Uitgelig | C22: Uitgelig | D22: OK as is
A23: World Heritage | B23: Wereld Erfenis | C23: Wêrelderfenis | D23: One word, with ê
A25: {n} in a pattern stands for a number the app fills in; keep it in the translation.

Sheet Summary
A1: App | B1: Strings | C1: Afrikaans translated | D1: isiZulu translated | E1: isiXhosa translated | F1: Sepedi translated | G1: Afrikaans blank | H1: isiZulu blank | I1: isiXhosa blank | J1: Sepedi blank
A2: TrustSquare | B2: =COUNTIF('All strings'!$B$2:$B$3210,A2) -> 2232 | C2: =SUMPRODUCT(('All strings'!$B$2:$B$3210=$A2)*(LEN('All strings'!$E$2:$E$3210)>0)) -> 2210 | D2: =SUMPRODUCT(('All strings'!$B$2:$B$3210=$A2)*(LEN('All strings'!$F$2:$F$3210)>0)) -> 1896 | E2: =SUMPRODUCT(('All strings'!$B$2:$B$3210=$A2)*(LEN('All strings'!$G$2:$G$3210)>0)) -> 1766 | F2: =SUMPRODUCT(('All strings'!$B$2:$B$3210=$A2)*(LEN('All strings'!$H$2:$H$3210)>0)) -> 1773 | G2: =SUMPRODUCT(('All strings'!$B$2:$B$3210=$A2)*(LEN('All strings'!$E$2:$E$3210)=0)) -> 22 | H2: =SUMPRODUCT(('All strings'!$B$2:$B$3210=$A2)*(LEN('All strings'!$F$2:$F$3210)=0)) -> 336 | I2: =SUMPRODUCT(('All strings'!$B$2:$B$3210=$A2)*(LEN('All strings'!$G$2:$G$3210)=0)) -> 466 | J2: =SUMPRODUCT(('All strings'!$B$2:$B$3210=$A2)*(LEN('All strings'!$H$2:$H$3210)=0)) -> 459
A3: Quick | B3: =COUNTIF('All strings'!$B$2:$B$3210,A3) -> 919 | C3: =SUMPRODUCT(('All strings'!$B$2:$B$3210=$A3)*(LEN('All strings'!$E$2:$E$3210)>0)) -> 919 | D3: =SUMPRODUCT(('All strings'!$B$2:$B$3210=$A3)*(LEN('All strings'!$F$2:$F$3210)>0)) -> 919 | E3: =SUMPRODUCT(('All strings'!$B$2:$B$3210=$A3)*(LEN('All strings'!$G$2:$G$3210)>0)) -> 919 | F3: =SUMPRODUCT(('All strings'!$B$2:$B$3210=$A3)*(LEN('All strings'!$H$2:$H$3210)>0)) -> 919 | G3: =SUMPRODUCT(('All strings'!$B$2:$B$3210=$A3)*(LEN('All strings'!$E$2:$E$3210)=0)) -> 0 | H3: =SUMPRODUCT(('All strings'!$B$2:$B$3210=$A3)*(LEN('All strings'!$F$2:$F$3210)=0)) -> 0 | I3: =SUMPRODUCT(('All strings'!$B$2:$B$3210=$A3)*(LEN('All strings'!$G$2:$G$3210)=0)) -> 0 | J3: =SUMPRODUCT(('All strings'!$B$2:$B$3210=$A3)*(LEN('All strings'!$H$2:$H$3210)=0)) -> 0
A4: Trader | B4: =COUNTIF('All strings'!$B$2:$B$3210,A4) -> 58 | C4: =SUMPRODUCT(('All strings'!$B$2:$B$3210=$A4)*(LEN('All strings'!$E$2:$E$3210)>0)) -> 58 | D4: =SUMPRODUCT(('All strings'!$B$2:$B$3210=$A4)*(LEN('All strings'!$F$2:$F$3210)>0)) -> 58 | E4: =SUMPRODUCT(('All strings'!$B$2:$B$3210=$A4)*(LEN('All strings'!$G$2:$G$3210)>0)) -> 58 | F4: =SUMPRODUCT(('All strings'!$B$2:$B$3210=$A4)*(LEN('All strings'!$H$2:$H$3210)>0)) -> 58 | G4: =SUMPRODUCT(('All strings'!$B$2:$B$3210=$A4)*(LEN('All strings'!$E$2:$E$3210)=0)) -> 0 | H4: =SUMPRODUCT(('All strings'!$B$2:$B$3210=$A4)*(LEN('All strings'!$F$2:$F$3210)=0)) -> 0 | I4: =SUMPRODUCT(('All strings'!$B$2:$B$3210=$A4)*(LEN('All strings'!$G$2:$G$3210)=0)) -> 0 | J4: =SUMPRODUCT(('All strings'!$B$2:$B$3210=$A4)*(LEN('All strings'!$H$2:$H$3210)=0)) -> 0
A5: Total | B5: =SUM(B2:B4) -> 3209 | C5: =SUM(C2:C4) -> 3187 | D5: =SUM(D2:D4) -> 2873 | E5: =SUM(E2:E4) -> 2743 | F5: =SUM(F2:F4) -> 2750 | G5: =SUM(G2:G4) -> 22 | H5: =SUM(H2:H4) -> 336 | I5: =SUM(I2:I4) -> 466 | J5: =SUM(J2:J4) -> 459
A7: Content & legal sheet holds a further 1262 auto-translated texts; Kept in English holds 506 phrases.

Sheet All strings
A1: ID | B1: App | C1: Kind | D1: English (source) | E1: Afrikaans | F1: isiZulu | G1: isiXhosa | H1: Sepedi | I1: Flags
A2: T0001 | B2: TrustSquare | C2: App dictionary | D2: AI examples on | E2: KI-voorbeelde aan | F2: Izibonelo ze-AI zivuliwe | G2: Imizekelo ye-AI ivuliwe | H2: Mehlala ya AI e butswe
A3: T0002 | B3: TrustSquare | C3: App dictionary | D3: AI examples off | E3: KI-voorbeelde af | F3: Izibonelo ze-AI zivaliwe | H3: Mehlala ya AI e timilwe | I3: isiXhosa: Blank
A4: T0003 | B4: TrustSquare | C4: App dictionary | D4: AI examples are shown, below the real listings. | E4: KI-voorbeelde word gewys, onder die regte advertensies. | F4: Izibonelo ze-AI ziboniswa ngezansi kwezikhangiso zangempela. | G4: Imizekelo ye-AI iboniswa ngezantsi kweentengiso zokwenyani. | I4: Sepedi: Blank
A5: T0004 | B5: TrustSquare | C5: App dictionary | D5: AI examples are hidden. Only real listings show. | E5: KI-voorbeelde is versteek. Net regte advertensies wys. | I5: isiZulu: Blank; isiXhosa: Blank; Sepedi: Blank
A6: T0005 | B6: TrustSquare | C6: App dictionary | D6: Show AI examples | E6: Wys KI-voorbeelde | I6: isiZulu: Blank; isiXhosa: Blank; Sepedi: Blank
A7: T0006 | B7: TrustSquare | C7: App dictionary | D7: Show or hide the AI example listings | E7: Wys of versteek die KI-voorbeeldadvertensies | I7: isiZulu: Blank; isiXhosa: Blank; Sepedi: Blank
A8: T0007 | B8: TrustSquare | C8: App dictionary | D8: Me | E8: Ek | F8: Mina | G8: Mna | H8: Nna
A9: T0008 | B9: TrustSquare | C9: App dictionary | D9: No | E9: Nee | F9: Cha | G9: Hayi | H9: Aowa
A10: T0009 | B10: TrustSquare | C10: App dictionary | D10: to | E10: tot | F10: ku | G10: ukuya | H10: go
A11: T0010 | B11: TrustSquare | C11: App dictionary | D11: All | E11: Alles | F11: Konke | G11: Zonke | H11: Ka moka
A12: T0011 | B12: TrustSquare | C12: App dictionary | D12: Any | E12: Enige | F12: Noma yini | G12: Nayiphi | H12: Efe goba efe
A13: T0012 | B13: TrustSquare | C13: App dictionary | D13: Art | E13: Kuns | F13: Ubuciko | G13: Ubugcisa | H13: Bokgabo
A14: T0013 | B14: TrustSquare | C14: App dictionary | D14: Fri | E14: Vr | F14: Lwesihlanu | G14: Hla | H14: Hlan
A15: T0014 | B15: TrustSquare | C15: App dictionary | D15: Mon | E15: Ma | F15: Msombuluko | G15: Mvu | H15: Moš
A16: T0015 | B16: TrustSquare | C16: App dictionary | D16: Sat | E16: Sa | F16: Mgqibelo | G16: Mgq | H16: Mok
A17: T0016 | B17: TrustSquare | C17: App dictionary | D17: Sun | E17: So | F17: Sonto | G17: Caw | H17: Son
A18: T0017 | B18: TrustSquare | C18: App dictionary | D18: Thu | E18: Do | F18: Lwesine | G18: Sin | H18: Ne
A19: T0018 | B19: TrustSquare | C19: App dictionary | D19: Tue | E19: Di | F19: Lwesibili | G19: Bin | H19: Bed
... A25: T0024 | B25: TrustSquare | C25: App dictionary | D25: Back | E25: Terug | F25: Emuva | G25: Buyela | H25: Morago
A26: T0025 | B26: TrustSquare | C26: App dictionary | D26: Buzz | E26: Buzz | F26: Buzz | G26: Buzz | H26: Buzz | I26: Afrikaans: Same as English; isiZulu: Same as English; isiXhosa: Same as English; Sepedi: Same as English
A27: T0026 | B27: TrustSquare | C27: App dictionary | D27: Cars | E27: Motors | F27: Izimoto | G27: Iimoto | H27: Dikoloi
A28: T0027 | B28: TrustSquare | C28: App dictionary | D28: Chef | E28: Sjef | F28: Umpheki | G28: Umpheki | H28: Shefo
A29: T0028 | B29: TrustSquare | C29: App dictionary | D29: City | E29: Stad | F29: Idolobha | G29: Isixeko | H29: Toropo
A30: T0029 | B30: TrustSquare | C30: App dictionary | D30: Cook | E30: Kok | F30: Umpheki | G30: Umpheki | H30: Moapei
A31: T0030 | B31: TrustSquare | C31: App dictionary | D31: Cuba | E31: Kuba | F31: iCuba | G31: Cuba | H31: Cuba | I31: isiXhosa: Same as English; Sepedi: Same as English
A32: T0031 | B32: TrustSquare | C32: App dictionary | D32: Edit | E32: Wysig | F32: Hlela | G32: Hlela | H32: Fetola
A33: T0032 | B33: TrustSquare | C33: App dictionary | D33: Farm | E33: Plaas | F33: Ipulazi | G33: Ifama | H33: Polase
A34: T0033 | B34: TrustSquare | C34: App dictionary | D34: Free | E34: Gratis | F34: Mahhala | G34: Simahla | H34: Mahala
A35: T0034 | B35: TrustSquare | C35: App dictionary | D35: Home | E35: Tuis | F35: Ikhaya | G35: Ekhaya | H35: Gae
A36: T0035 | B36: TrustSquare | C36: App dictionary | D36: Iraq | E36: Irak | F36: i-Iraq | G36: Iraq | H36: Iraq | I36: isiXhosa: Same as English; Sepedi: Same as English
A37: T0036 | B37: TrustSquare | C37: App dictionary | D37: Make | E37: Maak | F37: Yenza | G37: Yenza | H37: Dira
A38: T0037 | B38: TrustSquare | C38: App dictionary | D38: Mode | E38: Modus | F38: Imodi | G38: Imo | H38: Mokgwa
A39: T0038 | B39: TrustSquare | C39: App dictionary | D39: More | E39: Meer | F39: Okunye | G39: Ngaphezulu | H39: Tše dingwe
A40: T0039 | B40: TrustSquare | C40: App dictionary | D40: Oman | E40: Oman | F40: i-Oman | G40: Oman | H40: Oman | I40: Afrikaans: Same as English; isiXhosa: Same as English; Sepedi: Same as English
A41: T0040 | B41: TrustSquare | C41: App dictionary | D41: Pool | E41: Swembad | F41: Iphuli | G41: Idama lokuqubha | H41: Bodiba bja go rutha
A42: T0041 | B42: TrustSquare | C42: App dictionary | D42: Save | E42: Stoor | F42: Londoloza | G42: Gcina | H42: Boloka
A43: T0042 | B43: TrustSquare | C43: App dictionary | D43: Sell | E43: Verkoop | F43: Thengisa | G43: Thengisa | H43: Rekiša
A44: T0043 | B44: TrustSquare | C44: App dictionary | D44: Sent | E44: Gestuur | F44: Kuthunyelwe | G44: Ithunyelwe | H44: E rometšwe
A45: T0044 | B45: TrustSquare | C45: App dictionary | D45: Solo | E45: Alleen | F45: Wedwa | G45: Ndedwa | H45: Nnoši
...

Sheet Afrikaans review
A1: ID | B1: App | C1: English (source) | D1: Current Afrikaans | E1: Flag | F1: Corrected Afrikaans | G1: Comment
A2: T0001 | B2: TrustSquare | C2: AI examples on | D2: KI-voorbeelde aan
A3: T0002 | B3: TrustSquare | C3: AI examples off | D3: KI-voorbeelde af
A4: T0003 | B4: TrustSquare | C4: AI examples are shown, below the real listings. | D4: KI-voorbeelde word gewys, onder die regte advertensies.
A5: T0004 | B5: TrustSquare | C5: AI examples are hidden. Only real listings show. | D5: KI-voorbeelde is versteek. Net regte advertensies wys.
A6: T0005 | B6: TrustSquare | C6: Show AI examples | D6: Wys KI-voorbeelde
A7: T0006 | B7: TrustSquare | C7: Show or hide the AI example listings | D7: Wys of versteek die KI-voorbeeldadvertensies
A8: T0007 | B8: TrustSquare | C8: Me | D8: Ek
A9: T0008 | B9: TrustSquare | C9: No | D9: Nee
A10: T0009 | B10: TrustSquare | C10: to | D10: tot
A11: T0010 | B11: TrustSquare | C11: All | D11: Alles
A12: T0011 | B12: TrustSquare | C12: Any | D12: Enige
A13: T0012 | B13: TrustSquare | C13: Art | D13: Kuns
... A25: T0024 | B25: TrustSquare | C25: Back | D25: Terug
A26: T0025 | B26: TrustSquare | C26: Buzz | D26: Buzz | E26: Same as English (fine for names/brands)
A27: T0026 | B27: TrustSquare | C27: Cars | D27: Motors
A28: T0027 | B28: TrustSquare | C28: Chef | D28: Sjef
A29: T0028 | B29: TrustSquare | C29: City | D29: Stad
A30: T0029 | B30: TrustSquare | C30: Cook | D30: Kok
A31: T0030 | B31: TrustSquare | C31: Cuba | D31: Kuba
A32: T0031 | B32: TrustSquare | C32: Edit | D32: Wysig
A33: T0032 | B33: TrustSquare | C33: Farm | D33: Plaas
A34: T0033 | B34: TrustSquare | C34: Free | D34: Gratis
A35: T0034 | B35: TrustSquare | C35: Home | D35: Tuis
A36: T0035 | B36: TrustSquare | C36: Iraq | D36: Irak
A37: T0036 | B37: TrustSquare | C37: Make | D37: Maak
A38: T0037 | B38: TrustSquare | C38: Mode | D38: Modus
A39: T0038 | B39: TrustSquare | C39: More | D39: Meer
A40: T0039 | B40: TrustSquare | C40: Oman | D40: Oman | E40: Same as English (fine for names/brands)
A41: T0040 | B41: TrustSquare | C41: Pool | D41: Swembad
A42: T0041 | B42: TrustSquare | C42: Save | D42: Stoor
A43: T0042 | B43: TrustSquare | C43: Sell | D43: Verkoop
A44: T0043 | B44: TrustSquare | C44: Sent | D44: Gestuur
A45: T0044 | B45: TrustSquare | C45: Solo | D45: Alleen
A46: T0045 | B46: TrustSquare | C46: Tags | D46: Etikette
A47: T0046 | B47: TrustSquare | C47: Team | D47: Span
A48: T0047 | B48: TrustSquare | C48: Term | D48: Termyn
A49: T0048 | B49: TrustSquare | C49: Tier | D49: Vlak
A50: T0049 | B50: TrustSquare | C50: bulk | D50: grootmaat
A51: T0050 | B51: TrustSquare | C51: this | D51: hierdie
...

Sheet isiZulu review
A1: ID | B1: App | C1: English (source) | D1: Current isiZulu | E1: Flag | F1: Corrected isiZulu | G1: Comment
A2: T0001 | B2: TrustSquare | C2: AI examples on | D2: Izibonelo ze-AI zivuliwe
A3: T0002 | B3: TrustSquare | C3: AI examples off | D3: Izibonelo ze-AI zivaliwe
A4: T0003 | B4: TrustSquare | C4: AI examples are shown, below the real listings. | D4: Izibonelo ze-AI ziboniswa ngezansi kwezikhangiso zangempela.
A5: T0004 | B5: TrustSquare | C5: AI examples are hidden. Only real listings show. | E5: Blank — app shows English
A6: T0005 | B6: TrustSquare | C6: Show AI examples | E6: Blank — app shows English
A7: T0006 | B7: TrustSquare | C7: Show or hide the AI example listings | E7: Blank — app shows English
A8: T0007 | B8: TrustSquare | C8: Me | D8: Mina
A9: T0008 | B9: TrustSquare | C9: No | D9: Cha
A10: T0009 | B10: TrustSquare | C10: to | D10: ku
A11: T0010 | B11: TrustSquare | C11: All | D11: Konke
A12: T0011 | B12: TrustSquare | C12: Any | D12: Noma yini
A13: T0012 | B13: TrustSquare | C13: Art | D13: Ubuciko
A14: T0013 | B14: TrustSquare | C14: Fri | D14: Lwesihlanu
A15: T0014 | B15: TrustSquare | C15: Mon | D15: Msombuluko
A16: T0015 | B16: TrustSquare | C16: Sat | D16: Mgqibelo
A17: T0016 | B17: TrustSquare | C17: Sun | D17: Sonto
A18: T0017 | B18: TrustSquare | C18: Thu | D18: Lwesine
A19: T0018 | B19: TrustSquare | C19: Tue | D19: Lwesibili
... A25: T0024 | B25: TrustSquare | C25: Back | D25: Emuva
A26: T0025 | B26: TrustSquare | C26: Buzz | D26: Buzz | E26: Same as English (fine for names/brands)
A27: T0026 | B27: TrustSquare | C27: Cars | D27: Izimoto
A28: T0027 | B28: TrustSquare | C28: Chef | D28: Umpheki
A29: T0028 | B29: TrustSquare | C29: City | D29: Idolobha
A30: T0029 | B30: TrustSquare | C30: Cook | D30: Umpheki
A31: T0030 | B31: TrustSquare | C31: Cuba | D31: iCuba
A32: T0031 | B32: TrustSquare | C32: Edit | D32: Hlela
A33: T0032 | B33: TrustSquare | C33: Farm | D33: Ipulazi
A34: T0033 | B34: TrustSquare | C34: Free | D34: Mahhala
A35: T0034 | B35: TrustSquare | C35: Home | D35: Ikhaya
A36: T0035 | B36: TrustSquare | C36: Iraq | D36: i-Iraq
A37: T0036 | B37: TrustSquare | C37: Make | D37: Yenza
A38: T0037 | B38: TrustSquare | C38: Mode | D38: Imodi
... A60: T0059 | B60: TrustSquare | C60: Email | D60: I-imeyili
A61: T0060 | B61: TrustSquare | C61: Haiko | D61: Haiko | E61: Same as English (fine for names/brands)
A62: T0061 | B62: TrustSquare | C62: House | D62: Indlu
A63: T0062 | B63: TrustSquare | C63: India | D63: iNdiya
A64: T0063 | B64: TrustSquare | C64: Italy | D64: i-Italy
A65: T0064 | B65: TrustSquare | C65: Kenya | D65: iKenya
A66: T0065 | B66: TrustSquare | C66: Legal | D66: Ezomthetho
...

Sheet isiXhosa review
A1: ID | B1: App | C1: English (source) | D1: Current isiXhosa | E1: Flag | F1: Corrected isiXhosa | G1: Comment
A2: T0001 | B2: TrustSquare | C2: AI examples on | D2: Imizekelo ye-AI ivuliwe
A3: T0002 | B3: TrustSquare | C3: AI examples off | E3: Blank — app shows English
A4: T0003 | B4: TrustSquare | C4: AI examples are shown, below the real listings. | D4: Imizekelo ye-AI iboniswa ngezantsi kweentengiso zokwenyani.
A5: T0004 | B5: TrustSquare | C5: AI examples are hidden. Only real listings show. | E5: Blank — app shows English
A6: T0005 | B6: TrustSquare | C6: Show AI examples | E6: Blank — app shows English
A7: T0006 | B7: TrustSquare | C7: Show or hide the AI example listings | E7: Blank — app shows English
A8: T0007 | B8: TrustSquare | C8: Me | D8: Mna
A9: T0008 | B9: TrustSquare | C9: No | D9: Hayi
A10: T0009 | B10: TrustSquare | C10: to | D10: ukuya
A11: T0010 | B11: TrustSquare | C11: All | D11: Zonke
A12: T0011 | B12: TrustSquare | C12: Any | D12: Nayiphi
A13: T0012 | B13: TrustSquare | C13: Art | D13: Ubugcisa
A14: T0013 | B14: TrustSquare | C14: Fri | D14: Hla
A15: T0014 | B15: TrustSquare | C15: Mon | D15: Mvu
A16: T0015 | B16: TrustSquare | C16: Sat | D16: Mgq
A17: T0016 | B17: TrustSquare | C17: Sun | D17: Caw
A18: T0017 | B18: TrustSquare | C18: Thu | D18: Sin
A19: T0018 | B19: TrustSquare | C19: Tue | D19: Bin
... A25: T0024 | B25: TrustSquare | C25: Back | D25: Buyela
A26: T0025 | B26: TrustSquare | C26: Buzz | D26: Buzz | E26: Same as English (fine for names/brands)
A27: T0026 | B27: TrustSquare | C27: Cars | D27: Iimoto
A28: T0027 | B28: TrustSquare | C28: Chef | D28: Umpheki
A29: T0028 | B29: TrustSquare | C29: City | D29: Isixeko
A30: T0029 | B30: TrustSquare | C30: Cook | D30: Umpheki
A31: T0030 | B31: TrustSquare | C31: Cuba | D31: Cuba | E31: Same as English (fine for names/brands)
A32: T0031 | B32: TrustSquare | C32: Edit | D32: Hlela
A33: T0032 | B33: TrustSquare | C33: Farm | D33: Ifama
A34: T0033 | B34: TrustSquare | C34: Free | D34: Simahla
A35: T0034 | B35: TrustSquare | C35: Home | D35: Ekhaya
A36: T0035 | B36: TrustSquare | C36: Iraq | D36: Iraq | E36: Same as English (fine for names/brands)
A37: T0036 | B37: TrustSquare | C37: Make | D37: Yenza
A38: T0037 | B38: TrustSquare | C38: Mode | D38: Imo
A39: T0038 | B39: TrustSquare | C39: More | D39: Ngaphezulu
A40: T0039 | B40: TrustSquare | C40: Oman | D40: Oman | E40: Same as English (fine for names/brands)
A41: T0040 | B41: TrustSquare | C41: Pool | D41: Idama lokuqubha
A42: T0041 | B42: TrustSquare | C42: Save | D42: Gcina
A43: T0042 | B43: TrustSquare | C43: Sell | D43: Thengisa
A44: T0043 | B44: TrustSquare | C44: Sent | D44: Ithunyelwe
A45: T0044 | B45: TrustSquare | C45: Solo | D45: Ndedwa
...

Sheet Sepedi review
A1: ID | B1: App | C1: English (source) | D1: Current Sepedi | E1: Flag | F1: Corrected Sepedi | G1: Comment
A2: T0001 | B2: TrustSquare | C2: AI examples on | D2: Mehlala ya AI e butswe
A3: T0002 | B3: TrustSquare | C3: AI examples off | D3: Mehlala ya AI e timilwe
A4: T0003 | B4: TrustSquare | C4: AI examples are shown, below the real listings. | E4: Blank — app shows English
A5: T0004 | B5: TrustSquare | C5: AI examples are hidden. Only real listings show. | E5: Blank — app shows English
A6: T0005 | B6: TrustSquare | C6: Show AI examples | E6: Blank — app shows English
A7: T0006 | B7: TrustSquare | C7: Show or hide the AI example listings | E7: Blank — app shows English
A8: T0007 | B8: TrustSquare | C8: Me | D8: Nna
A9: T0008 | B9: TrustSquare | C9: No | D9: Aowa
A10: T0009 | B10: TrustSquare | C10: to | D10: go
A11: T0010 | B11: TrustSquare | C11: All | D11: Ka moka
A12: T0011 | B12: TrustSquare | C12: Any | D12: Efe goba efe
A13: T0012 | B13: TrustSquare | C13: Art | D13: Bokgabo
A14: T0013 | B14: TrustSquare | C14: Fri | D14: Hlan
A15: T0014 | B15: TrustSquare | C15: Mon | D15: Moš
A16: T0015 | B16: TrustSquare | C16: Sat | D16: Mok
A17: T0016 | B17: TrustSquare | C17: Sun | D17: Son
A18: T0017 | B18: TrustSquare | C18: Thu | D18: Ne
A19: T0018 | B19: TrustSquare | C19: Tue | D19: Bed
... A25: T0024 | B25: TrustSquare | C25: Back | D25: Morago
A26: T0025 | B26: TrustSquare | C26: Buzz | D26: Buzz | E26: Same as English (fine for names/brands)
A27: T0026 | B27: TrustSquare | C27: Cars | D27: Dikoloi
A28: T0027 | B28: TrustSquare | C28: Chef | D28: Shefo
A29: T0028 | B29: TrustSquare | C29: City | D29: Toropo
A30: T0029 | B30: TrustSquare | C30: Cook | D30: Moapei
A31: T0030 | B31: TrustSquare | C31: Cuba | D31: Cuba | E31: Same as English (fine for names/brands)
A32: T0031 | B32: TrustSquare | C32: Edit | D32: Fetola
A33: T0032 | B33: TrustSquare | C33: Farm | D33: Polase
A34: T0033 | B34: TrustSquare | C34: Free | D34: Mahala
A35: T0034 | B35: TrustSquare | C35: Home | D35: Gae
A36: T0035 | B36: TrustSquare | C36: Iraq | D36: Iraq | E36: Same as English (fine for names/brands)
A37: T0036 | B37: TrustSquare | C37: Make | D37: Dira
A38: T0037 | B38: TrustSquare | C38: Mode | D38: Mokgwa
A39: T0038 | B39: TrustSquare | C39: More | D39: Tše dingwe
A40: T0039 | B40: TrustSquare | C40: Oman | D40: Oman | E40: Same as English (fine for names/brands)
A41: T0040 | B41: TrustSquare | C41: Pool | D41: Bodiba bja go rutha
A42: T0041 | B42: TrustSquare | C42: Save | D42: Boloka
A43: T0042 | B43: TrustSquare | C43: Sell | D43: Rekiša
A44: T0043 | B44: TrustSquare | C44: Sent | D44: E rometšwe
A45: T0044 | B45: TrustSquare | C45: Solo | D45: Nnoši
...

Sheet Content & legal
A1: ID | B1: App | C1: Kind | D1: English (source) | E1: Afrikaans | F1: isiZulu | G1: isiXhosa | H1: Sepedi
A2: C0001 | B2: TrustSquare | C2: Content / legal / places | D2: Taj Mahal | F2: I-Taj Mahal
A3: C0002 | B3: TrustSquare | C3: Content / legal / places | D3: Machu Picchu | F3: I-Machu Picchu
A4: C0003 | B4: TrustSquare | C4: Content / legal / places | D4: Petra | F4: I-Petra
A5: C0004 | B5: TrustSquare | C5: Content / legal / places | D5: Angkor Wat | F5: I-Angkor Wat
A6: C0005 | B6: TrustSquare | C6: Content / legal / places | D6: Stonehenge | F6: I-Stonehenge
A7: C0006 | B7: TrustSquare | C7: Content / legal / places | D7: Mont-Saint-Michel | F7: I-Mont-Saint-Michel
A8: C0007 | B8: TrustSquare | C8: Content / legal / places | D8: Alhambra | F8: I-Alhambra
A9: C0008 | B9: TrustSquare | C9: Content / legal / places | D9: Chichen Itza | F9: I-Chichen Itza
A10: C0009 | B10: TrustSquare | C10: Content / legal / places | D10: Cappadocia (Göreme) | E10: Cappadocië (Göreme) | F10: I-Cappadocia (Göreme)
A11: C0010 | B11: TrustSquare | C11: Content / legal / places | D11: Jiuzhaigou Valley | E11: Jiuzhaigou-vallei | F11: I-Jiuzhaigou Valley
A12: C0011 | B12: TrustSquare | C12: Content / legal / places | D12: Timbuktu | E12: Timboektoe | F12: I-Timbuktu
A13: C0012 | B13: TrustSquare | C13: Content / legal / places | D13: Hagia Sophia, Istanbul | F13: I-Hagia Sophia, Istanbul
A14: C0013 | B14: TrustSquare | C14: Content / legal / places | D14: From A$540per night | E14: Van A$540per night
A15: C0014 | B15: TrustSquare | C15: Content / legal / places | D15: From £350per night | E15: Van £350per night
A16: C0015 | B16: TrustSquare | C16: Content / legal / places | D16: From $420per night | E16: Van $420per night
A17: C0016 | B17: TrustSquare | C17: Content / legal / places | D17: From €180per night | E17: Van €180per night
A18: C0017 | B18: TrustSquare | C18: Content / legal / places | D18: From KSh60,000per night | E18: Van KSh60,000per night
A19: C0018 | B19: TrustSquare | C19: Content / legal / places | D19: £95per person | E19: £95 per persoon
A20: C0019 | B20: TrustSquare | C20: Content / legal / places | D20: $180per person | E20: $180 per persoon
A21: C0020 | B21: TrustSquare | C21: Content / legal / places | D21: €1,450per person | E21: €1,450 per persoon
A22: C0021 | B22: TrustSquare | C22: Content / legal / places | D22: From KSh18,000per night | E22: Vanaf KSh18,000 per nag
A23: C0022 | B23: TrustSquare | C23: Content / legal / places | D23: R1,850per person | E23: R1,850 per persoon
A24: C0023 | B24: TrustSquare | C24: Content / legal / places | D24: A$5,900per person | E24: A$5,900 per persoon
A25: C0024 | B25: TrustSquare | C25: Content / legal / places | D25: £4,450per person | E25: £4,450 per persoon
... A45: C0044 | B45: TrustSquare | C45: Content / legal / places | D45: your city · narrow your search | E45: jou stad · vernou jou soektog
A46: C0045 | B46: TrustSquare | C46: Content / legal / places | D46: Sarek National Park | E46: Sarek Nasionale Park | F46: Isipala Sezimbali Se-Sarek | G46: iSarek National Park | H46: Phaka ya Bosetšhaba ya Sarek
A47: C0046 | B47: TrustSquare | C47: Content / legal / places | D47: Killarney National Park | E47: Killarney Nasionale Park | F47: Isipala Sezimbali SeKillarney | G47: iKillarney National Park | H47: Phaka ya Bosetšhaba ya Killarney
A48: C0047 | B48: TrustSquare | C48: Content / legal / places | D48: Doñana National Park | E48: Doñana Nasionale Park | F48: Isipala Sezimbali Se-Doñana | G48: iDoñana National Park | H48: Phaka ya Bosetšhaba ya Doñana
A49: C0048 | B49: TrustSquare | C49: Content / legal / places | D49: Gran Paradiso National Park | E49: Gran Paradiso Nasionale Park | F49: Isipala Sezimbali Se-Gran Paradiso | G49: iGran Paradiso National Park | H49: Phaka ya Bosetšhaba ya Gran Paradiso
A50: C0049 | B50: TrustSquare | C50: Content / legal / places | D50: Berchtesgaden National Park | E50: Berchtesgaden Nasionale Park | F50: Isipala Sezimbali SeeBerchtesgaden | G50: iBerchtesgaden National Park | H50: Phaka ya Bosetšhaba ya Berchtesgaden
A51: C0050 | B51: TrustSquare | C51: Content / legal / places | D51: Royal Chitwan National Park | E51: Royal Chitwan Nasionale Park | F51: Isipala Sezimbali SeRoyal Chitwan | G51: iRoyal Chitwan National Park | H51: Phaka ya Bosetšhaba ya Royal Chitwan
A52: C0051 | B52: TrustSquare | C52: Content / legal / places | D52: Zion National Park | E52: Zion Nasionale Park | F52: Isipala Sezimbali Se-Zion | G52: iZion National Park | H52: Phaka ya Bosetšhaba ya Zion
A53: C0052 | B53: TrustSquare | C53: Content / legal / places | D53: Glacier National Park (U.S.) | E53: Glacier Nasionale Park (U.S.) | F53: Isipala Sezimbali Se-Glacier | G53: iGlacier National Park (U.S.) | H53: Phaka ya Bosetšhaba ya Glacier (U.S.)
A54: C0053 | B54: TrustSquare | C54: Content / legal / places | D54: Jasper National Park | E54: Jasper Nasionale Park | F54: Isipala Sezimbali Se-Jasper | G54: iJasper National Park | H54: Phaka ya Bosetšhaba ya Jasper
A55: C0054 | B55: TrustSquare | C55: Content / legal / places | D55: Manuel Antonio National Park | E55: Manuel Antonio Nasionale Park | F55: Isipala Sezimbali SeManuel Antonio | G55: iManuel Antonio National Park | H55: Phaka ya Bosetšhaba ya Manuel Antonio
A56: C0055 | B56: TrustSquare | C56: Content / legal / places | D56: Louvre Museum | E56: Louvre-museum | G56: Imyuziyam yaseLouvre
A57: C0056 | B57: TrustSquare | C57: Content / legal / places | D57: Hermitage Museum | E57: Hermitage-museum | G57: Imyuziyam yaseHermitage
A58: C0057 | B58: TrustSquare | C58: Content / legal / places | D58: Pergamon Museum | E58: Pergamon-museum | F58: I-Pergamon Museum | G58: Imyuziyam yasePergamon
A59: C0058 | B59: TrustSquare | C59: Content / legal / places | D59: Historic Centre of Porto | E59: Historiese sentrum van Porto | F59: Indawo Yesikhathi Esasele YePorto | G59: Iziko Elidala lePorto | H59: Bogare bja Histori bja Porto
...

Sheet Kept in English
A1: English (leave as is)
A2: 1 Tuppence ($2) deducted only on seller acceptance
A3: 1. Definitions & Interpretation
A4: 1. Tuppence is non-refundable platform currency.
A5: 1.1 Definitions
A6: 1.2 Interpretation
A7: 10. Disputes, Enforcement & Liability
A8: 10.1 User Disputes
A9: 10.2 Platform Enforcement
A10: 10.3 Pre-Dispute Negotiation (60 Days)
A11: 10.4 Binding Arbitration
A12: 10.5 Consumer Protection Act Override
... A507: ⚠️ These were read from your photos — nothing was looked up in a vehicle database. On less common models the AI can be confidently wrong, so please check every figure against your own papers before confirming.
